Workbook
Name SegmentaciónDeDatos_Apellido_y_Nombre: #N/A
Name SegmentaciónDeDatos_Apellido_y_Nombre1: #N/A
Name SegmentaciónDeDatos_Apellido_y_Nombre2: #N/A
Name SegmentaciónDeDatos_Consultorio: #N/A
Name SegmentaciónDeDatos_dia: #N/A
Name SegmentaciónDeDatos_dia1: #N/A
Name SegmentaciónDeDatos_dia11: #N/A
Name SegmentaciónDeDatos_dia2: #N/A
Name SegmentaciónDeDatos_dia3: #N/A
Name SegmentaciónDeDatos_PRESTACION___Inserte_1_Fila_x_Prestacion_x_Paciente_: #N/A
Name SegmentaciónDeDatos_Servicio: #N/A
Name SegmentaciónDeDatos_Servicio1: #N/A
Name SegmentaciónDeDatos_Servicio2: #N/A

Sheet pacientes
A1: OPERADOR | B1: ESTADO | C1: AUTORIZACION | D1: TURNO | E1: PACIENTE | F1: O. SOCIAL | G1: CUIL | H1: N° Afiliado | I1: Columna1
A2: MCaceres | B2: En proceso | D2: T.M | E2: FERREYRA SALAS ENZO ABEL | F2: IOSFA | G2: 20 56900905 8 | H2: 0-21046903
A3: MCaceres | B3: En proceso | D3: T.M | E3: TRONCOSO GONZALO | F3: IOSFA | G3: 20 565679 7 | H3: 56729-4/01
A4: MCaceres | B4: En proceso | D4: T.M | E4: CASCO SANCHEZ MAXIMO GIOVANNI | F4: IOSFA | G4: 20 58801951 6 | H4: 3188870/01
A5: MCaceres | B5: En proceso | D5: T.T | E5: CESTARES GARRAZA FABRIZIO IVAN | F5: IOSFA | G5: 23 41115266 9 | H5: 41115266
A6: MCaceres | B6: En proceso | D6: T.T | E6: JIMENEZ ALEJANDRO EZEQUIEL | F6: IOSFA | G6: 23 52157750 9 | H6: 52157750
A7: MCaceres | B7: En proceso | D7: T.T | E7: PEREYRA OVIEDO MARTINA AYLEN | F7: IOSFA | G7: 27 49959924 8 | H7: 297338/13
A8: MCaceres | B8: En proceso | D8: T.T | E8: ROBIN FELIPE BENJAMIN | F8: IOSFA | G8: 20 57566237 5 | H8: 57566237
A9: MCaceres | B9: En proceso | D9: T.T | E9: TOLEDO LIAM ANGEL | F9: IOSFA | G9: 20 55286279 2 | H9: 55286279
A10: MCaceres | B10: En proceso | D10: T.T | E10: VACA LAUTARO DANTE | F10: IOSFA | G10: 20 55523986 7 | H10: 38790511
A11: JHidalgo | B11: En proceso | D11: T.T | E11: FLINT CONSTANTINO | F11: IOSFA | G11: 20 53263976 0 | H11: 102085/02
A12: JHidalgo | B12: En proceso | D12: T.T | E12: BUSTAMANTE MATEO JOEL | F12: IOSFA | G12: 20 55605475 5 | H12: 32123010
A13: JHidalgo | B13: En proceso | D13: T.T | E13: PATAGUA THEO VALENTIN | F13: IOSFA | G13: 20 53627821 5 | H13: 387656/4
A14: JHidalgo | B14: En proceso | D14: T.M | E14: MARTINEZ MARTA OLINDA | F14: IOSFA | G14: 27 13841061 2 | H14: 124418/01
A15: JHidalgo | B15: En proceso | D15: T.T | E15: MONTENEGRO DEVRAN SAMUEL | F15: IOSFA | G15: 20 55288753 1 | H15: 55288753
A16: JHidalgo | B16: En proceso | D16: T.T | E16: HOYOS LEIVA IGNACIO | F16: IOSFA | G16: 20 57360441 6 | H16: 57360441
A17: JHidalgo | B17: En proceso | D17: T.T | E17: PONCE BARGAS MIA AGOSTINA | F17: IOSFA | G17: 27 52158638 4 | H17: 207122/2
A18: JHidalgo | B18: En proceso | D18: T.T | E18: PONCE BARGAS TOMAS | F18: IOSFA | G18: 20 54474550 7 | H18: 20712203
A19: JHidalgo | B19: En proceso | D19: T.M | E19: CUELLO DANIEL NICOLAS | F19: IOSFA | G19: 20 10873745 0 | H19: 11109400
A20: JHidalgo | B20: En proceso | D20: T.T | E20: CATRAMBONI FABRIZZIO FRANCESCO | F20: IOSFA | G20: 20 56242157 3 | H20: 204884/02
A21: JHidalgo | B21: En proceso | D21: T.T | E21: DALLIA ASHLY KAORI | F21: IOSFA | G21: 27 56035740 6 | H21: 321585/13
A22: JHidalgo | B22: En proceso | D22: T.T | E22: RODRIGUEZ LEON PATRICIO | F22: IOSFA | G22: 20 54016666 9 | H22: 321878/13
A23: MCaceres | B23: En proceso | D23: T.T | E23: VILLARREAL BENJAMIN IGNACIO | F23: IOSFA | G23: 23 58162597 9 | H23: 3148685
A24: MCaceres | B24: En proceso | D24: T.T | E24: VARGAS PAZ MIA ISABELLA | F24: IOSFA | G24: 27 57192465 5 | H24: 57192465
A25: JHidalgo | B25: En proceso | D25: T.M | E25: VILCHEZ JORGE FABIAN | F25: OSUTHGRA | G25: 20 29607441 2 | H25: 27056084342 / 01
A26: JHidalgo | B26: En proceso | D26: T.M | E26: CARABAJAL PINEDA THIAGO EZEQUIEL | F26: OSUTHGRA | G26: 20 50326180 5 | H26: 20229450175/04
A27: JHidalgo | B27: En proceso | D27: T.M | E27: HEREDIA BAUTISTA SAMUEL | F27: OSUTHGRA | G27: 20 56065972 6 | H27: 20426424488 3
A28: JHidalgo | B28: En proceso | D28: T.T | E28: ZAPATA LAUTARO JESUS | F28: OSUTHGRA | G28: 20 46034103 6 | H28: 20261797500 / 02
A29: JHidalgo | B29: En proceso | D29: T.M | E29: ESQUIVEL ALVARO SAMUEL | F29: OSUTHGRA | G29: 20 59043837 6 | H29: 20353252233 /02
A30: JHidalgo | B30: En proceso | D30: T.M | E30: PINTO LOURDES VICTORIA | F30: OSUTHGRA | G30: 27 57529063 4 | H30: 20405185793/ 01
A31: JHidalgo | B31: En proceso | D31: T.T | E31: IRUSTA MENA DANIEL EMILIANO | F31: OSUTHGRA | G31: 20 50937171 8 | H31: 27332011095 /01
A32: JHidalgo | B32: En proceso | D32: T.T | E32: IRUSTA MENA IVAN LISANDRO | F32: OSUTHGRA | G32: 20 52235175 0 | H32: 27332011095 /02
A33: JHidalgo | B33: En proceso | D33: T.T | E33: LIMACHI DARIO ALEXIS | F33: OSUTHGRA | G33: 20 45595176 4 | H33: 23185586294 /01
A34: JHidalgo | B34: En proceso | D34: T.T | E34: OLIVARES LUNA APRIL BELEN | F34: OSUTHGRA | G34: 27 95240834 3 | H34: 20952408330 /03
A35: JHidalgo | B35: En proceso | D35: T.T | E35: OLIVARES LUNA JOSUE DANYEL | F35: OSUTHGRA | G35: 20 56538779 1 | H35: 20952408330 /05
A36: JHidalgo | B36: En proceso | D36: T.T | E36: LOZA JUAN IGNACIO | F36: OSUTHGRA | G36: 20 49404543 6 | H36: 27333209255 /02
A37: JHidalgo | D37: T.T | E37: LOZA TICIANO BENJAMIN | F37: OSUTHGRA | G37: 20 50000750 9 | H37: 27333209255 /03
A38: JHidalgo | D38: T.T | E38: FUNES ANGELA LUCIA | F38: OSUTHGRA | G38: 27 50080999 5 | H38: 27291103214 /03
A39: JHidalgo | D39: T.T | E39: TELLO FRANCISCO MANUEL | F39: OSUTHGRA | G39: 20 55287655 6 | H39: 20219023058 /04
A40: JHidalgo | D40: T.T | E40: LLANES BUSTOS BRISA MILAGROS DESIREE | F40: OSUTHGRA | G40: 27 49287777 3 | H40: 27352124392 /02
...

Sheet lista ordenada
A1: LISTA PACIENTES ORDENADA | B1: CUIL | C1: OBRA SOCIAL
A2: {=+_xlfn._xlws.SORT(_xlfn.UNIQUE(Tabla2[PACIENTE]),1,1)} -> ACOSTA CELESTE SOLEDAD | B2: =+_xlfn.XLOOKUP(A2,pacientes!E:E,pacientes!G:G,0,FALSE) -> 27 38183145 6 | C2: =+_xlfn.XLOOKUP(A2,pacientes!E:E,pacientes!F:F,0,FALSE) -> OSUTHGRA
A3: AGUIRRE FRANCISCO SIMON | B3: =+_xlfn.XLOOKUP(A3,pacientes!E:E,pacientes!G:G,0,FALSE) -> 20 50594826 3 | C3: =+_xlfn.XLOOKUP(A3,pacientes!E:E,pacientes!F:F,0,FALSE) -> OSUTHGRA
A4: AMAYA TADEO BENJAMIN | B4: =+_xlfn.XLOOKUP(A4,pacientes!E:E,pacientes!G:G,0,FALSE) -> 0 | C4: =+_xlfn.XLOOKUP(A4,pacientes!E:E,pacientes!F:F,0,FALSE) -> OSBLYCA (SERVIRED)
A5: ARGUELLO THOMAS ALEJO | B5: =+_xlfn.XLOOKUP(A5,pacientes!E:E,pacientes!G:G,0,FALSE) -> 20 47820033 2 | C5: =+_xlfn.XLOOKUP(A5,pacientes!E:E,pacientes!F:F,0,FALSE) -> OSPE
A6: BALTAZAR BERNAL ALISON | B6: =+_xlfn.XLOOKUP(A6,pacientes!E:E,pacientes!G:G,0,FALSE) -> 20 58388479 4 | C6: =+_xlfn.XLOOKUP(A6,pacientes!E:E,pacientes!F:F,0,FALSE) -> OSPES
A7: BALTAZAR BERNAL HANNA MARTINA | B7: =+_xlfn.XLOOKUP(A7,pacientes!E:E,pacientes!G:G,0,FALSE) -> 27 56979317 9 | C7: =+_xlfn.XLOOKUP(A7,pacientes!E:E,pacientes!F:F,0,FALSE) -> OSPES
A8: BALTAZAR BERNAL ISABELLA MILENA | B8: =+_xlfn.XLOOKUP(A8,pacientes!E:E,pacientes!G:G,0,FALSE) -> 27 59293525 8 | C8: =+_xlfn.XLOOKUP(A8,pacientes!E:E,pacientes!F:F,0,FALSE) -> OSPES
A9: BARRERA WALTER DANIEL | B9: =+_xlfn.XLOOKUP(A9,pacientes!E:E,pacientes!G:G,0,FALSE) -> 20 12741216 3 | C9: =+_xlfn.XLOOKUP(A9,pacientes!E:E,pacientes!F:F,0,FALSE) -> OSPLYFC
A10: BARRIONUEVO ZAIRA MAYLEN | B10: =+_xlfn.XLOOKUP(A10,pacientes!E:E,pacientes!G:G,0,FALSE) -> 27 49501662 0 | C10: =+_xlfn.XLOOKUP(A10,pacientes!E:E,pacientes!F:F,0,FALSE) -> OSUTHGRA
A11: BRUNO MARCOS GABRIEL | B11: =+_xlfn.XLOOKUP(A11,pacientes!E:E,pacientes!G:G,0,FALSE) -> 20 46125634 2 | C11: =+_xlfn.XLOOKUP(A11,pacientes!E:E,pacientes!F:F,0,FALSE) -> OSUTHGRA
A12: BUSTAMANTE MATEO JOEL | B12: =+_xlfn.XLOOKUP(A12,pacientes!E:E,pacientes!G:G,0,FALSE) -> 20 55605475 5 | C12: =+_xlfn.XLOOKUP(A12,pacientes!E:E,pacientes!F:F,0,FALSE) -> IOSFA
A13: CABILLON PEDROZO SELENIA AIMÉ | B13: =+_xlfn.XLOOKUP(A13,pacientes!E:E,pacientes!G:G,0,FALSE) -> 27 54777860 5 | C13: =+_xlfn.XLOOKUP(A13,pacientes!E:E,pacientes!F:F,0,FALSE) -> OSCCPTAC (CAMIONEROS)
A14: CALLEJO LIONEL ALEXANDER | B14: =+_xlfn.XLOOKUP(A14,pacientes!E:E,pacientes!G:G,0,FALSE) -> 0 | C14: =+_xlfn.XLOOKUP(A14,pacientes!E:E,pacientes!F:F,0,FALSE) -> OSBLYCA (SERVIRED)
... A118: ZAPATA LAUTARO JESUS | B118: =+_xlfn.XLOOKUP(A118,pacientes!E:E,pacientes!G:G,0,FALSE) -> 20 46034103 6 | C118: =+_xlfn.XLOOKUP(A118,pacientes!E:E,pacientes!F:F,0,FALSE) -> OSUTHGRA
A119: 0 | B119: =+_xlfn.XLOOKUP(A119,pacientes!E:E,pacientes!G:G,0,FALSE) -> 0 | C119: =+_xlfn.XLOOKUP(A119,pacientes!E:E,pacientes!F:F,0,FALSE) -> 0
B120: =+_xlfn.XLOOKUP(A120,pacientes!E:E,pacientes!G:G,0,FALSE) -> 0 | C120: =+_xlfn.XLOOKUP(A120,pacientes!E:E,pacientes!F:F,0,FALSE) -> 0
B121: =+_xlfn.XLOOKUP(A121,pacientes!E:E,pacientes!G:G,0,FALSE) -> 0 | C121: =+_xlfn.XLOOKUP(A121,pacientes!E:E,pacientes!F:F,0,FALSE) -> 0
B122: =+_xlfn.XLOOKUP(A122,pacientes!E:E,pacientes!G:G,0,FALSE) -> 0 | C122: =+_xlfn.XLOOKUP(A122,pacientes!E:E,pacientes!F:F,0,FALSE) -> 0
B123: =+_xlfn.XLOOKUP(A123,pacientes!E:E,pacientes!G:G,0,FALSE) -> 0 | C123: =+_xlfn.XLOOKUP(A123,pacientes!E:E,pacientes!F:F,0,FALSE) -> 0
B124: =+_xlfn.XLOOKUP(A124,pacientes!E:E,pacientes!G:G,0,FALSE) -> 0 | C124: =+_xlfn.XLOOKUP(A124,pacientes!E:E,pacientes!F:F,0,FALSE) -> 0
B125: =+_xlfn.XLOOKUP(A125,pacientes!E:E,pacientes!G:G,0,FALSE) -> 0 | C125: =+_xlfn.XLOOKUP(A125,pacientes!E:E,pacientes!F:F,0,FALSE) -> 0
B126: =+_xlfn.XLOOKUP(A126,pacientes!E:E,pacientes!G:G,0,FALSE) -> 0 | C126: =+_xlfn.XLOOKUP(A126,pacientes!E:E,pacientes!F:F,0,FALSE) -> 0
B127: =+_xlfn.XLOOKUP(A127,pacientes!E:E,pacientes!G:G,0,FALSE) -> 0 | C127: =+_xlfn.XLOOKUP(A127,pacientes!E:E,pacientes!F:F,0,FALSE) -> 0
B128: =+_xlfn.XLOOKUP(A128,pacientes!E:E,pacientes!G:G,0,FALSE) -> 0 | C128: =+_xlfn.XLOOKUP(A128,pacientes!E:E,pacientes!F:F,0,FALSE) -> 0
B129: =+_xlfn.XLOOKUP(A129,pacientes!E:E,pacientes!G:G,0,FALSE) -> 0 | C129: =+_xlfn.XLOOKUP(A129,pacientes!E:E,pacientes!F:F,0,FALSE) -> 0
B130: =+_xlfn.XLOOKUP(A130,pacientes!E:E,pacientes!G:G,0,FALSE) -> 0 | C130: =+_xlfn.XLOOKUP(A130,pacientes!E:E,pacientes!F:F,0,FALSE) -> 0
B131: =+_xlfn.XLOOKUP(A131,pacientes!E:E,pacientes!G:G,0,FALSE) -> 0 | C131: =+_xlfn.XLOOKUP(A131,pacientes!E:E,pacientes!F:F,0,FALSE) -> 0
... B269: =+_xlfn.XLOOKUP(A269,pacientes!E:E,pacientes!G:G,0,FALSE) -> 0 | C269: =+_xlfn.XLOOKUP(A269,pacientes!E:E,pacientes!F:F,0,FALSE) -> 0

Sheet BASE PACIENTES 2026
A1: Source.Name | B1: OPERADOR | C1: ESTADO | D1: AUTORIZACION | E1: TURNO | F1: PACIENTE | G1: O. SOCIAL | H1: CUIL | I1: N° Afiliado | J1: MÓDULO
A2: PLANES 2026.xlsx | B2: MCaceres | C2: BAJA | D2: BAJA | E2: T.M | F2: FERREYRA SALAS ENZO ABEL | G2: IOSFA | H2: 20 56900905 8 | I2: 0-21046903 | J2: REHAB.INTENSIVO + CAI
A3: PLANES 2026.xlsx | B3: MCaceres | C3: ACTIVO | D3: 46387 | E3: T.M | F3: TRONCOSO GONZALO | G3: IOSFA | H3: 20 0565679 7 | I3: 56729-4/01 | J3: REHAB.SIMPLE
A4: PLANES 2026.xlsx | B4: MCaceres | C4: ACTIVO | D4: 46387 | E4: T.M | F4: CASCO SANCHEZ MAXIMO GIOVANNI | G4: IOSFA | H4: 20 58881951 6 | I4: 3188870/01 | J4: REHAB. SIMPLE + CAI
A5: PLANES 2026.xlsx | B5: MCaceres | C5: ACTIVO | D5: 46299 | E5: T.T | F5: CESTARES GARRAZA FABRIZIO IVAN | G5: IOSFA | H5: 23 41115266 9 | I5: 41115266 | J5: REHAB.SIMPLE
A6: PLANES 2026.xlsx | B6: MCaceres | C6: ACTIVO | D6: 46387 | E6: T.T | F6: JIMENEZ ALEJANDRO EZEQUIEL | G6: IOSFA | H6: 23 52157750 9 | I6: 52157750 | J6: REHAB.SIMPLE
A7: PLANES 2026.xlsx | B7: MCaceres | C7: BAJA | D7: BAJA | E7: T.T | F7: PEREYRA OVIEDO MARTINA AYLEN | G7: IOSFA | H7: 27 49959924 8 | I7: 297338/13 | J7: REHAB. SIMPLE + CAI
A8: PLANES 2026.xlsx | B8: MCaceres | C8: ACTIVO | D8: 46387 | E8: T.T | F8: ROBIN FELIPE BENJAMIN | G8: IOSFA | H8: 20 57566237 5 | I8: 57566237 | J8: REHAB.INTENSIVO + CAI
A9: PLANES 2026.xlsx | B9: MCaceres | C9: ACTIVO | D9: 46387 | E9: T.T | F9: TOLEDO LIAM ANGEL | G9: IOSFA | H9: 20 55286279 2 | I9: 55286279 | J9: REHAB. SIMPLE + CAI
A10: PLANES 2026.xlsx | B10: MCaceres | C10: BAJA | D10: BAJA | E10: T.T | F10: VACA LAUTARO DANTE | G10: IOSFA | H10: 20 55523986 7 | I10: 38790511 | J10: REHAB. SIMPLE + CAI
A11: PLANES 2026.xlsx | B11: JHidalgo | C11: ACTIVO | D11: 46387 | E11: T.T | F11: FLINT CONSTANTINO | G11: IOSFA | H11: 20 53263976 0 | I11: 102085/02 | J11: REHAB. SIMPLE + CAI
A12: PLANES 2026.xlsx | B12: JHidalgo | C12: BAJA | E12: T.T | F12: BUSTAMANTE MATEO JOEL | G12: IOSFA | H12: 20 55605475 5 | I12: 32123010 | J12: REHAB.INTENSIVO + CAI
A13: PLANES 2026.xlsx | B13: JHidalgo | C13: ACTIVO | D13: 46356 | E13: T.T | F13: PATAGUA THEO VALENTIN | G13: IOSFA | H13: 20 53627821 5 | I13: 387656/4 | J13: REHAB. SIMPLE + CAI
A14: PLANES 2026.xlsx | B14: JHidalgo | C14: ACTIVO | D14: 46387 | E14: T.M | F14: MARTINEZ MARTA OLINDA | G14: IOSFA | H14: 27 13841061 2 | I14: 124418/01 | J14: REHAB.SIMPLE
A15: PLANES 2026.xlsx | B15: JHidalgo | C15: ACTIVO | D15: 46387 | E15: T.T | F15: MONTENEGRO DEVRAN SAMUEL | G15: IOSFA | H15: 20 55288753 1 | I15: 55288753 | J15: REHAB. SIMPLE + CAI
A16: PLANES 2026.xlsx | B16: JHidalgo | C16: ACTIVO | D16: 46356 | E16: T.T | F16: HOYOS LEIVA IGNACIO | G16: IOSFA | H16: 20 57360441 6 | I16: 57360441 | J16: REHAB. SIMPLE + CAI
A17: PLANES 2026.xlsx | B17: JHidalgo | C17: ACTIVO | D17: 46387 | E17: T.T | F17: PONCE BARGAS MIA AGOSTINA | G17: IOSFA | H17: 27 52158638 4 | I17: 207122/2 | J17: REHAB. SIMPLE + CAI
A18: PLANES 2026.xlsx | B18: JHidalgo | C18: ACTIVO | D18: 46387 | E18: T.T | F18: PONCE BARGAS TOMAS | G18: IOSFA | H18: 20 54474550 7 | I18: 20712203 | J18: SESION + CAI
A19: PLANES 2026.xlsx | B19: JHidalgo | C19: ACTIVO | D19: 46387 | E19: T.M | F19: CUELLO DANIEL NICOLAS | G19: IOSFA | H19: 20 10873745 0 | I19: 11109400 | J19: REHAB.SIMPLE
A20: PLANES 2026.xlsx | B20: JHidalgo | C20: ACTIVO | D20: 46356 | E20: T.T | F20: CATRAMBONI FABRIZZIO FRANCESCO | G20: IOSFA | H20: 20 56242157 3 | I20: 204884/02 | J20: REHAB. SIMPLE + CAI
A21: PLANES 2026.xlsx | B21: JHidalgo | C21: ACTIVO | D21: 46387 | E21: T.T | F21: DALLIA ASHLY KAORI | G21: IOSFA | H21: 27 56035740 6 | I21: 321585/13 | J21: REHAB. SIMPLE + CAI
A22: PLANES 2026.xlsx | B22: JHidalgo | C22: ACTIVO | D22: 46317 | E22: T.T | F22: RODRIGUEZ LEON PATRICIO | G22: IOSFA | H22: 20 54016666 9 | I22: 321878/13 | J22: REHAB. SIMPLE + CAI
A23: PLANES 2026.xlsx | B23: MCaceres | C23: BAJA | D23: BAJA | E23: T.T | F23: VILLARREAL BENJAMIN IGNACIO | G23: IOSFA | H23: 23 58162597 9 | I23: 3148685 | J23: REHAB.INTENSIVO + CAI
A24: PLANES 2026.xlsx | B24: MCaceres | C24: BAJA | D24: BAJA | E24: T.T | F24: VARGAS PAZ MIA ISABELLA | G24: IOSFA | H24: 27 57192465 5 | I24: 57192465 | J24: REHAB. SIMPLE + CAI
A25: PLANES 2026.xlsx | B25: JHidalgo | C25: ACTIVO | D25: 46203 | E25: T.M | F25: VILCHEZ JORGE FABIAN | G25: OSUTHGRA | H25: 20 29607441 2 | I25: 27056084342 / 01 | J25: REHAB.SIMPLE
A26: PLANES 2026.xlsx | B26: JHidalgo | C26: ACTIVO | D26: 46387 | E26: T.M | F26: CARABAJAL PINEDA THIAGO EZEQUIEL | G26: OSUTHGRA | H26: 20 50326180 5 | I26: 20229450175/04 | J26: REHAB. SIMPLE + CAI
A27: PLANES 2026.xlsx | B27: JHidalgo | C27: ACTIVO | D27: 46387 | E27: T.M | F27: HEREDIA BAUTISTA SAMUEL | G27: OSUTHGRA | H27: 20 56065972 6 | I27: 20426424488 3 | J27: REHAB.INTENSIVO + CAI
A28: PLANES 2026.xlsx | B28: JHidalgo | C28: ACTIVO | D28: 46387 | E28: T.T | F28: ZAPATA LAUTARO JESUS | G28: OSUTHGRA | H28: 20 46034103 6 | I28: 20261797500 / 02 | J28: REHAB.SIMPLE
A29: PLANES 2026.xlsx | B29: JHidalgo | C29: ACTIVO | D29: 46387 | E29: T.M | F29: ESQUIVEL ALVARO SAMUEL | G29: OSUTHGRA | H29: 20 59043837 6 | I29: 20353252233 /02 | J29: REHAB.INTENSIVO + CAI
A30: PLANES 2026.xlsx | B30: JHidalgo | C30: BAJA | D30: BAJA | E30: T.M | F30: PINTO LOURDES VICTORIA | G30: OSUTHGRA | H30: 27 5729063 4 | I30: 20405185793/ 01 | J30: REHAB.INTENSIVO + CAI
A31: PLANES 2026.xlsx | B31: JHidalgo | C31: BAJA | D31: BAJA | E31: T.T | F31: IRUSTA MENA DANIEL EMILIANO | G31: OSUTHGRA | H31: 20 50937171 8 | I31: 27332011095 /01 | J31: REHAB.SIMPLE
A32: PLANES 2026.xlsx | B32: JHidalgo | C32: BAJA | D32: BAJA | E32: T.T | F32: IRUSTA MENA IVAN LISANDRO | G32: OSUTHGRA | H32: 20 52235175 0 | I32: 27332011095 /02 | J32: REHAB.SIMPLE
A33: PLANES 2026.xlsx | B33: JHidalgo | C33: ACTIVO | D33: 46387 | E33: T.T | F33: LIMACHI DARIO ALEXIS | G33: OSUTHGRA | H33: 20 45595176 4 | I33: 23185586294 /01 | J33: REHAB.SIMPLE
A34: PLANES 2026.xlsx | B34: JHidalgo | C34: ACTIVO | D34: 46387 | E34: T.T | F34: OLIVARES LUNA APRIL BELEN | G34: OSUTHGRA | H34: 27 95240834 3 | I34: 20952408330 /03 | J34: REHAB. SIMPLE + CAI
A35: PLANES 2026.xlsx | B35: JHidalgo | C35: ACTIVO | D35: 46387 | E35: T.T | F35: OLIVARES LUNA JOSUE DANYEL | G35: OSUTHGRA | H35: 20 56538779 1 | I35: 20952408330 /05 | J35: REHAB.INTENSIVO + CAI
A36: PLANES 2026.xlsx | B36: JHidalgo | C36: ACTIVO | D36: 46387 | E36: T.T | F36: LOZA JUAN IGNACIO | G36: OSUTHGRA | H36: 20 49404543 6 | I36: 27333209255 /02 | J36: REHAB.SIMPLE
A37: PLANES 2026.xlsx | B37: JHidalgo | C37: ACTIVO | D37: 46387 | E37: T.M | F37: LOZA TICIANO BENJAMIN | G37: OSUTHGRA | H37: 20 50000750 9 | I37: 27333209255 /03 | J37: REHAB. SIMPLE + CAI
A38: PLANES 2026.xlsx | B38: JHidalgo | C38: ACTIVO | D38: 46387 | E38: T.T | F38: FUNES ANGELA LUCIA | G38: OSUTHGRA | H38: 27 50080999 5 | I38: 27291103214 /03 | J38: REHAB. SIMPLE + CAI
A39: PLANES 2026.xlsx | B39: JHidalgo | C39: ACTIVO | D39: 46387 | E39: T.T | F39: TELLO FRANCISCO MANUEL | G39: OSUTHGRA | H39: 20 55287655 6 | I39: 20219023058 /04 | J39: REHAB.INTENSIVO + CAI
A40: PLANES 2026.xlsx | B40: JHidalgo | C40: Pendiente | E40: T.T | F40: LLANES BUSTOS BRISA MILAGROS DESIREE | G40: OSUTHGRA | H40: 27 49287777 3 | I40: 27352124392 /02 | J40: REHAB. SIMPLE + CAI
...

Sheet BASE DE CARGA
A1: PACIENTE | B1: CUIL | C1: OBRA SOCIAL | D1: MODULO | E1: TURNO | F1: PRESTACION (Inserte 1 Fila x Prestacion x Paciente) | G1: sesiones semanales | H1: profesional | I1: dia | J1: hora | K1: Consultorio | L1: dia copia | M1: hora copia | N1: ACCION | O1: FECHA ACCION | P1: MOTIVO | Q1: MOTIVO2 | R1: MOTIVO3 | S1: MOTIVO4 | T1: MOTIVO5 | U1: DNI
A2: MOYANO SANTINO LEONEL | B2: =+_xlfn.XLOOKUP(carga[[#This Row],[PACIENTE]],BASE_PACIENTES_2026[PACIENTE],BASE_PACIENTES_2026[CUIL],0,0) -> 20 52156526 9 | C2: =+_xlfn.XLOOKUP(carga[[#This Row],[PACIENTE]],BASE_PACIENTES_2026[PACIENTE],BASE_PACIENTES_2026[O. SOCIAL],0,0) -> OSPEJ | D2: =+_xlfn.XLOOKUP(carga[[#This Row],[PACIENTE]],BASE_PACIENTES_2026[PACIENTE],BASE_PACIENTES_2026[MÓDULO],0,0) -> REHAB.INTENSIVO + CAI | E2: T.T | F2: Psico Fliar | G2: 1 | H2: DOMINGUEZ Mercedes Lorena | I2: Martes | J2: 0.61458333 | K2: R.16 | L2: =+carga[[#This Row],[dia]] -> Martes | M2: =+carga[[#This Row],[hora]] -> 0.61458333 | P2: empezo el 18/6 | U2: =+MID(carga[[#This Row],[CUIL]],4,8) -> 52156526
A3: ALANIS GINA | B3: =+_xlfn.XLOOKUP(carga[[#This Row],[PACIENTE]],BASE_PACIENTES_2026[PACIENTE],BASE_PACIENTES_2026[CUIL],0,0) -> 27 56063004 8 | C3: =+_xlfn.XLOOKUP(carga[[#This Row],[PACIENTE]],BASE_PACIENTES_2026[PACIENTE],BASE_PACIENTES_2026[O. SOCIAL],0,0) -> OSTACC | D3: =+_xlfn.XLOOKUP(carga[[#This Row],[PACIENTE]],BASE_PACIENTES_2026[PACIENTE],BASE_PACIENTES_2026[MÓDULO],0,0) -> REHAB.INTENSIVO + CAI | E3: T.T | F3: Fono | G3: 1 | H3: CASTRO Lucia Macarena | I3: Lunes | J3: 0.64583333 | K3: R.3 | L3: =+carga[[#This Row],[dia]] -> Lunes | M3: =+carga[[#This Row],[hora]] -> 0.64583333 | U3: =+MID(carga[[#This Row],[CUIL]],4,8) -> 56063004
A4: FIGUEROA IVAN PEDRO | B4: =+_xlfn.XLOOKUP(carga[[#This Row],[PACIENTE]],BASE_PACIENTES_2026[PACIENTE],BASE_PACIENTES_2026[CUIL],0,0) -> 20 56061366 1 | C4: =+_xlfn.XLOOKUP(carga[[#This Row],[PACIENTE]],BASE_PACIENTES_2026[PACIENTE],BASE_PACIENTES_2026[O. SOCIAL],0,0) -> OSPECOR | D4: =+_xlfn.XLOOKUP(carga[[#This Row],[PACIENTE]],BASE_PACIENTES_2026[PACIENTE],BASE_PACIENTES_2026[MÓDULO],0,0) -> REHAB.INTENSIVO | E4: T.T | F4: Fono | G4: 1 | H4: GIMENEZ Agustina | I4: Lunes | J4: 0.72916667 | K4: R.6 | L4: =+carga[[#This Row],[dia]] -> Lunes | M4: =+carga[[#This Row],[hora]] -> 0.72916667 | U4: =+MID(carga[[#This Row],[CUIL]],4,8) -> 56061366
A5: PERALTA ISAAC | B5: =+_xlfn.XLOOKUP(carga[[#This Row],[PACIENTE]],BASE_PACIENTES_2026[PACIENTE],BASE_PACIENTES_2026[CUIL],0,0) -> 20 59043324 2 | C5: =+_xlfn.XLOOKUP(carga[[#This Row],[PACIENTE]],BASE_PACIENTES_2026[PACIENTE],BASE_PACIENTES_2026[O. SOCIAL],0,0) -> OSSOELSAC | D5: =+_xlfn.XLOOKUP(carga[[#This Row],[PACIENTE]],BASE_PACIENTES_2026[PACIENTE],BASE_PACIENTES_2026[MÓDULO],0,0) -> REHAB.INTENSIVO + CAI | E5: T.T | F5: Fono | G5: 1 | H5: BARRIA VAZQUEZ Luciana ALicia | I5: Lunes | J5: 0.76041667 | K5: R.11 | L5: =+carga[[#This Row],[dia]] -> Lunes | M5: =+carga[[#This Row],[hora]] -> 0.76041667 | U5: =+MID(carga[[#This Row],[CUIL]],4,8) -> 59043324
A6: CORNEJO SAMIENTA FACUNDO NICOLAS | B6: =+_xlfn.XLOOKUP(carga[[#This Row],[PACIENTE]],BASE_PACIENTES_2026[PACIENTE],BASE_PACIENTES_2026[CUIL],0,0) -> 23 58385030 9 | C6: =+_xlfn.XLOOKUP(carga[[#This Row],[PACIENTE]],BASE_PACIENTES_2026[PACIENTE],BASE_PACIENTES_2026[O. SOCIAL],0,0) -> OSTACC | D6: =+_xlfn.XLOOKUP(carga[[#This Row],[PACIENTE]],BASE_PACIENTES_2026[PACIENTE],BASE_PACIENTES_2026[MÓDULO],0,0) -> REHAB.INTENSIVO + CAI | E6: T.T | F6: Fono | G6: 1 | H6: GOMEZ Agustina Daniela | I6: Lunes | J6: 0.79166667 | K6: R.1 | L6: =+carga[[#This Row],[dia]] -> Lunes | M6: =+carga[[#This Row],[hora]] -> 0.79166667 | U6: =+MID(carga[[#This Row],[CUIL]],4,8) -> 58385030
A7: GOMEZ SANTIAGO BENJAMIN | B7: =+_xlfn.XLOOKUP(carga[[#This Row],[PACIENTE]],BASE_PACIENTES_2026[PACIENTE],BASE_PACIENTES_2026[CUIL],0,0) -> 20 47475612 3 | C7: =+_xlfn.XLOOKUP(carga[[#This Row],[PACIENTE]],BASE_PACIENTES_2026[PACIENTE],BASE_PACIENTES_2026[O. SOCIAL],0,0) -> OSUTHGRA | D7: =+_xlfn.XLOOKUP(carga[[#This Row],[PACIENTE]],BASE_PACIENTES_2026[PACIENTE],BASE_PACIENTES_2026[MÓDULO],0,0) -> REHAB. SIMPLE + CAI | E7: T.M | F7: Psico | G7: 1 | H7: OLOCCO Maria Gabriela | I7: Viernes | J7: 0.44791667 | K7: R.12 | L7: =+carga[[#This Row],[dia]] -> Viernes | M7: =+carga[[#This Row],[hora]] -> 0.44791667 | N7: PENDIENTE | U7: =+MID(carga[[#This Row],[CUIL]],4,8) -> 47475612
A8: DESIMONE LUZ JAZMIN | B8: =+_xlfn.XLOOKUP(carga[[#This Row],[PACIENTE]],BASE_PACIENTES_2026[PACIENTE],BASE_PACIENTES_2026[CUIL],0,0) -> 27 54471368 5 | C8: =+_xlfn.XLOOKUP(carga[[#This Row],[PACIENTE]],BASE_PACIENTES_2026[PACIENTE],BASE_PACIENTES_2026[O. SOCIAL],0,0) -> OSMTT(SERVIRED) | D8: =+_xlfn.XLOOKUP(carga[[#This Row],[PACIENTE]],BASE_PACIENTES_2026[PACIENTE],BASE_PACIENTES_2026[MÓDULO],0,0) -> REHAB. SIMPLE + CAI | E8: T.T | F8: Psico | G8: 1 | H8: OLIVA Lucas Julian | I8: Lunes | J8: 0.67708333 | K8: R.5 | U8: =+MID(carga[[#This Row],[CUIL]],4,8) -> 54471368
A9: FURTADO JUAN JOSE | B9: =+_xlfn.XLOOKUP(carga[[#This Row],[PACIENTE]],BASE_PACIENTES_2026[PACIENTE],BASE_PACIENTES_2026[CUIL],0,0) -> 20 51034844 4 | C9: =+_xlfn.XLOOKUP(carga[[#This Row],[PACIENTE]],BASE_PACIENTES_2026[PACIENTE],BASE_PACIENTES_2026[O. SOCIAL],0,0) -> OSBLYCA (SERVIRED) | D9: =+_xlfn.XLOOKUP(carga[[#This Row],[PACIENTE]],BASE_PACIENTES_2026[PACIENTE],BASE_PACIENTES_2026[MÓDULO],0,0) -> REHAB.INTENSIVO | E9: T.T | F9: Fono | G9: 1 | H9: ARMOA Andrea Celeste | I9: Martes | J9: 0.64583333 | K9: R.11 | L9: =+carga[[#This Row],[dia]] -> Martes | M9: =+carga[[#This Row],[hora]] -> 0.64583333 | U9: =+MID(carga[[#This Row],[CUIL]],4,8) -> 51034844
A10: MOYA BRUNO CALIXTO | B10: =+_xlfn.XLOOKUP(carga[[#This Row],[PACIENTE]],BASE_PACIENTES_2026[PACIENTE],BASE_PACIENTES_2026[CUIL],0,0) -> 20 56764235 7 | C10: =+_xlfn.XLOOKUP(carga[[#This Row],[PACIENTE]],BASE_PACIENTES_2026[PACIENTE],BASE_PACIENTES_2026[O. SOCIAL],0,0) -> OSCEP (SIPSSA) | D10: =+_xlfn.XLOOKUP(carga[[#This Row],[PACIENTE]],BASE_PACIENTES_2026[PACIENTE],BASE_PACIENTES_2026[MÓDULO],0,0) -> REHAB.INTENSIVO + CAI | E10: T.T | F10: Fono | G10: 1 | H10: GIRAUDO MILAGROS VIRGINIA | I10: Martes | J10: 0.67708333 | K10: R.6 | L10: =+carga[[#This Row],[dia]] -> Martes | M10: =+carga[[#This Row],[hora]] -> 0.67708333 | U10: =+MID(carga[[#This Row],[CUIL]],4,8) -> 56764235
A11: VIVANCO CABRERA MATEO JOAQUIN | B11: =+_xlfn.XLOOKUP(carga[[#This Row],[PACIENTE]],BASE_PACIENTES_2026[PACIENTE],BASE_PACIENTES_2026[CUIL],0,0) -> 23 53508798 9 | C11: =+_xlfn.XLOOKUP(carga[[#This Row],[PACIENTE]],BASE_PACIENTES_2026[PACIENTE],BASE_PACIENTES_2026[O. SOCIAL],0,0) -> OSPATRONES | D11: =+_xlfn.XLOOKUP(carga[[#This Row],[PACIENTE]],BASE_PACIENTES_2026[PACIENTE],BASE_PACIENTES_2026[MÓDULO],0,0) -> REHAB.INTENSIVO + CAI | E11: T.T | F11: Fono | G11: 1 | H11: ARMOA Andrea Celeste | I11: Martes | J11: 0.61458333 | K11: R.11 | U11: =+MID(carga[[#This Row],[CUIL]],4,8) -> 53508798
A12: SUAREZ CELESTE ABRIL | B12: =+_xlfn.XLOOKUP(carga[[#This Row],[PACIENTE]],BASE_PACIENTES_2026[PACIENTE],BASE_PACIENTES_2026[CUIL],0,0) -> 27 48669102 1 | C12: =+_xlfn.XLOOKUP(carga[[#This Row],[PACIENTE]],BASE_PACIENTES_2026[PACIENTE],BASE_PACIENTES_2026[O. SOCIAL],0,0) -> OSPEJ | D12: =+_xlfn.XLOOKUP(carga[[#This Row],[PACIENTE]],BASE_PACIENTES_2026[PACIENTE],BASE_PACIENTES_2026[MÓDULO],0,0) -> REHAB.SIMPLE | E12: T.T | F12: Fono | G12: 1 | H12: CASTRO Lucia Macarena | I12: Martes | J12: 0.76041667 | K12: R.Gimnasio | U12: =+MID(carga[[#This Row],[CUIL]],4,8) -> 48669102
A13: AGUIRRE VILLAMIZAR OLIVER JOSE | B13: =+_xlfn.XLOOKUP(carga[[#This Row],[PACIENTE]],BASE_PACIENTES_2026[PACIENTE],BASE_PACIENTES_2026[CUIL],0,0) -> 20 57528226 2 | C13: =+_xlfn.XLOOKUP(carga[[#This Row],[PACIENTE]],BASE_PACIENTES_2026[PACIENTE],BASE_PACIENTES_2026[O. SOCIAL],0,0) -> GEA PREPAGA | D13: =+_xlfn.XLOOKUP(carga[[#This Row],[PACIENTE]],BASE_PACIENTES_2026[PACIENTE],BASE_PACIENTES_2026[MÓDULO],0,0) -> REHAB.INTENSIVO + CAI | E13: T.T | F13: Fono | G13: 1 | H13: GIRAUDO MILAGROS VIRGINIA | I13: Martes | J13: 0.79166667 | K13: R.6 | L13: =+carga[[#This Row],[dia]] -> Martes | M13: =+carga[[#This Row],[hora]] -> 0.79166667 | U13: =+MID(carga[[#This Row],[CUIL]],4,8) -> 57528226
A14: ALANIS GINA | B14: =+_xlfn.XLOOKUP(carga[[#This Row],[PACIENTE]],BASE_PACIENTES_2026[PACIENTE],BASE_PACIENTES_2026[CUIL],0,0) -> 27 56063004 8 | C14: =+_xlfn.XLOOKUP(carga[[#This Row],[PACIENTE]],BASE_PACIENTES_2026[PACIENTE],BASE_PACIENTES_2026[O. SOCIAL],0,0) -> OSTACC | D14: =+_xlfn.XLOOKUP(carga[[#This Row],[PACIENTE]],BASE_PACIENTES_2026[PACIENTE],BASE_PACIENTES_2026[MÓDULO],0,0) -> REHAB.INTENSIVO + CAI | E14: T.T | F14: Fono | G14: 1 | H14: CASTRO Lucia Macarena | I14: Miercoles | J14: 0.67708333 | K14: R.3 | L14: =+carga[[#This Row],[dia]] -> Miercoles | M14: =+carga[[#This Row],[hora]] -> 0.67708333 | U14: =+MID(carga[[#This Row],[CUIL]],4,8) -> 56063004
A15: AGUIRRE VILLAMIZAR OLIVER JOSE | B15: =+_xlfn.XLOOKUP(carga[[#This Row],[PACIENTE]],BASE_PACIENTES_2026[PACIENTE],BASE_PACIENTES_2026[CUIL],0,0) -> 20 57528226 2 | C15: =+_xlfn.XLOOKUP(carga[[#This Row],[PACIENTE]],BASE_PACIENTES_2026[PACIENTE],BASE_PACIENTES_2026[O. SOCIAL],0,0) -> GEA PREPAGA | D15: =+_xlfn.XLOOKUP(carga[[#This Row],[PACIENTE]],BASE_PACIENTES_2026[PACIENTE],BASE_PACIENTES_2026[MÓDULO],0,0) -> REHAB.INTENSIVO + CAI | E15: T.T | F15: Psico Fliar | G15: 1 | H15: FERNANDEZ WOLFF Katerin | I15: Jueves | J15: 0.72916667 | K15: R.7 | L15: =+carga[[#This Row],[dia]] -> Jueves | M15: =+carga[[#This Row],[hora]] -> 0.72916667 | U15: =+MID(carga[[#This Row],[CUIL]],4,8) -> 57528226
A16: MACHADO VIDELA BENJAMIN FRANCESCO | B16: =+_xlfn.XLOOKUP(carga[[#This Row],[PACIENTE]],BASE_PACIENTES_2026[PACIENTE],BASE_PACIENTES_2026[CUIL],0,0) -> 20 58387335 0 | C16: =+_xlfn.XLOOKUP(carga[[#This Row],[PACIENTE]],BASE_PACIENTES_2026[PACIENTE],BASE_PACIENTES_2026[O. SOCIAL],0,0) -> OSPENA | D16: =+_xlfn.XLOOKUP(carga[[#This Row],[PACIENTE]],BASE_PACIENTES_2026[PACIENTE],BASE_PACIENTES_2026[MÓDULO],0,0) -> REHAB.INTENSIVO + CAI | E16: T.T | F16: Fono | G16: 1 | H16: GIMENEZ Agustina | I16: Miercoles | J16: 0.64583333 | K16: R.6 | L16: =+carga[[#This Row],[dia]] -> Miercoles | M16: =+carga[[#This Row],[hora]] -> 0.64583333 | U16: =+MID(carga[[#This Row],[CUIL]],4,8) -> 58387335
B17: =+_xlfn.XLOOKUP(carga[[#This Row],[PACIENTE]],BASE_PACIENTES_2026[PACIENTE],BASE_PACIENTES_2026[CUIL],0,0) -> 0 | C17: =+_xlfn.XLOOKUP(carga[[#This Row],[PACIENTE]],BASE_PACIENTES_2026[PACIENTE],BASE_PACIENTES_2026[O. SOCIAL],0,0) -> 0 | D17: =+_xlfn.XLOOKUP(carga[[#This Row],[PACIENTE]],BASE_PACIENTES_2026[PACIENTE],BASE_PACIENTES_2026[MÓDULO],0,0) -> 0 | L17: =+carga[[#This Row],[dia]] -> 0 | M17: =+carga[[#This Row],[hora]] -> 0 | U17: =+MID(carga[[#This Row],[CUIL]],4,8)
A18: FIGUEROA IVAN PEDRO | B18: =+_xlfn.XLOOKUP(carga[[#This Row],[PACIENTE]],BASE_PACIENTES_2026[PACIENTE],BASE_PACIENTES_2026[CUIL],0,0) -> 20 56061366 1 | C18: =+_xlfn.XLOOKUP(carga[[#This Row],[PACIENTE]],BASE_PACIENTES_2026[PACIENTE],BASE_PACIENTES_2026[O. SOCIAL],0,0) -> OSPECOR | D18: =+_xlfn.XLOOKUP(carga[[#This Row],[PACIENTE]],BASE_PACIENTES_2026[PACIENTE],BASE_PACIENTES_2026[MÓDULO],0,0) -> REHAB.INTENSIVO | E18: T.T | F18: Fono | G18: 1 | H18: PETANAS Sofia Milagros | I18: Miercoles | J18: 0.72916667 | K18: R.5 | L18: =+carga[[#This Row],[dia]] -> Miercoles | M18: =+carga[[#This Row],[hora]] -> 0.72916667 | U18: =+MID(carga[[#This Row],[CUIL]],4,8) -> 56061366
A19: BETOLLI CATALINA | B19: =+_xlfn.XLOOKUP(carga[[#This Row],[PACIENTE]],BASE_PACIENTES_2026[PACIENTE],BASE_PACIENTES_2026[CUIL],0,0) -> 0 | C19: =+_xlfn.XLOOKUP(carga[[#This Row],[PACIENTE]],BASE_PACIENTES_2026[PACIENTE],BASE_PACIENTES_2026[O. SOCIAL],0,0) -> 0 | D19: =+_xlfn.XLOOKUP(carga[[#This Row],[PACIENTE]],BASE_PACIENTES_2026[PACIENTE],BASE_PACIENTES_2026[MÓDULO],0,0) -> 0 | E19: T.M | F19: Kine | G19: 1 | H19: CONDORI Jose Hugo | I19: Martes | J19: 0.33333333 | K19: R.Gimnasio | L19: =+carga[[#This Row],[dia]] -> Martes | M19: =+carga[[#This Row],[hora]] -> 0.33333333 | U19: =+MID(carga[[#This Row],[CUIL]],4,8)
A20: CATRAMBONI FABRIZZIO FRANCESCO | B20: =+_xlfn.XLOOKUP(carga[[#This Row],[PACIENTE]],BASE_PACIENTES_2026[PACIENTE],BASE_PACIENTES_2026[CUIL],0,0) -> 20 56242157 3 | C20: =+_xlfn.XLOOKUP(carga[[#This Row],[PACIENTE]],BASE_PACIENTES_2026[PACIENTE],BASE_PACIENTES_2026[O. SOCIAL],0,0) -> IOSFA | D20: =+_xlfn.XLOOKUP(carga[[#This Row],[PACIENTE]],BASE_PACIENTES_2026[PACIENTE],BASE_PACIENTES_2026[MÓDULO],0,0) -> REHAB. SIMPLE + CAI | E20: T.T | F20: Fono | G20: 1 | H20: CASTRO Lucia Macarena | I20: Miercoles | J20: 0.64583333 | K20: R.3 | L20: =+carga[[#This Row],[dia]] -> Miercoles | M20: =+carga[[#This Row],[hora]] -> 0.64583333 | U20: =+MID(carga[[#This Row],[CUIL]],4,8) -> 56242157
A21: REYES FERREYRA AIXA YAZMIN | B21: =+_xlfn.XLOOKUP(carga[[#This Row],[PACIENTE]],BASE_PACIENTES_2026[PACIENTE],BASE_PACIENTES_2026[CUIL],0,0) -> 27 55010247 7 | C21: =+_xlfn.XLOOKUP(carga[[#This Row],[PACIENTE]],BASE_PACIENTES_2026[PACIENTE],BASE_PACIENTES_2026[O. SOCIAL],0,0) -> OSTACC | D21: =+_xlfn.XLOOKUP(carga[[#This Row],[PACIENTE]],BASE_PACIENTES_2026[PACIENTE],BASE_PACIENTES_2026[MÓDULO],0,0) -> REHAB. SIMPLE + CAI | E21: T.T | F21: Fono | G21: 1 | H21: GOMEZ Agustina Daniela | I21: Jueves | J21: 0.64583333 | K21: R.4 | L21: =+carga[[#This Row],[dia]] -> Jueves | M21: =+carga[[#This Row],[hora]] -> 0.64583333 | U21: =+MID(carga[[#This Row],[CUIL]],4,8) -> 55010247
A22: FURTADO JUAN JOSE | B22: =+_xlfn.XLOOKUP(carga[[#This Row],[PACIENTE]],BASE_PACIENTES_2026[PACIENTE],BASE_PACIENTES_2026[CUIL],0,0) -> 20 51034844 4 | C22: =+_xlfn.XLOOKUP(carga[[#This Row],[PACIENTE]],BASE_PACIENTES_2026[PACIENTE],BASE_PACIENTES_2026[O. SOCIAL],0,0) -> OSBLYCA (SERVIRED) | D22: =+_xlfn.XLOOKUP(carga[[#This Row],[PACIENTE]],BASE_PACIENTES_2026[PACIENTE],BASE_PACIENTES_2026[MÓDULO],0,0) -> REHAB.INTENSIVO | E22: T.T | F22: Fono | G22: 1 | H22: ARMOA Andrea Celeste | I22: Jueves | J22: 0.67708333 | K22: R.11 | L22: =+carga[[#This Row],[dia]] -> Jueves | M22: =+carga[[#This Row],[hora]] -> 0.67708333 | U22: =+MID(carga[[#This Row],[CUIL]],4,8) -> 51034844
A23: AGUIRRE VILLAMIZAR OLIVER JOSE | B23: =+_xlfn.XLOOKUP(carga[[#This Row],[PACIENTE]],BASE_PACIENTES_2026[PACIENTE],BASE_PACIENTES_2026[CUIL],0,0) -> 20 57528226 2 | C23: =+_xlfn.XLOOKUP(carga[[#This Row],[PACIENTE]],BASE_PACIENTES_2026[PACIENTE],BASE_PACIENTES_2026[O. SOCIAL],0,0) -> GEA PREPAGA | D23: =+_xlfn.XLOOKUP(carga[[#This Row],[PACIENTE]],BASE_PACIENTES_2026[PACIENTE],BASE_PACIENTES_2026[MÓDULO],0,0) -> REHAB.INTENSIVO + CAI | E23: T.T | F23: Fono | G23: 1 | H23: GIRAUDO MILAGROS VIRGINIA | I23: Jueves | J23: 0.72916667 | K23: R.6 | L23: =+carga[[#This Row],[dia]] -> Jueves | M23: =+carga[[#This Row],[hora]] -> 0.72916667 | U23: =+MID(carga[[#This Row],[CUIL]],4,8) -> 57528226
A24: OBREGON JAZMIN | B24: =+_xlfn.XLOOKUP(carga[[#This Row],[PACIENTE]],BASE_PACIENTES_2026[PACIENTE],BASE_PACIENTES_2026[CUIL],0,0) -> 27 47577786 1 | C24: =+_xlfn.XLOOKUP(carga[[#This Row],[PACIENTE]],BASE_PACIENTES_2026[PACIENTE],BASE_PACIENTES_2026[O. SOCIAL],0,0) -> IOSFA | D24: =+_xlfn.XLOOKUP(carga[[#This Row],[PACIENTE]],BASE_PACIENTES_2026[PACIENTE],BASE_PACIENTES_2026[MÓDULO],0,0) -> REHAB.SIMPLE | E24: T.M | F24: Kine | G24: 1 | H24: CONDORI Jose Hugo | I24: Martes | J24: 0.51041667 | K24: R.Gimnasio | L24: =+carga[[#This Row],[dia]] -> Martes | M24: =+carga[[#This Row],[hora]] -> 0.51041667 | U24: =+MID(carga[[#This Row],[CUIL]],4,8) -> 47577786
A25: SUAREZ CELESTE ABRIL | B25: =+_xlfn.XLOOKUP(carga[[#This Row],[PACIENTE]],BASE_PACIENTES_2026[PACIENTE],BASE_PACIENTES_2026[CUIL],0,0) -> 27 48669102 1 | C25: =+_xlfn.XLOOKUP(carga[[#This Row],[PACIENTE]],BASE_PACIENTES_2026[PACIENTE],BASE_PACIENTES_2026[O. SOCIAL],0,0) -> OSPEJ | D25: =+_xlfn.XLOOKUP(carga[[#This Row],[PACIENTE]],BASE_PACIENTES_2026[PACIENTE],BASE_PACIENTES_2026[MÓDULO],0,0) -> REHAB.SIMPLE | E25: T.T | F25: Fono | G25: 1 | H25: CASTRO Lucia Macarena | I25: Jueves | J25: 0.79166667 | K25: R.3 | L25: =+carga[[#This Row],[dia]] -> Jueves | M25: =+carga[[#This Row],[hora]] -> 0.79166667 | U25: =+MID(carga[[#This Row],[CUIL]],4,8) -> 48669102
A26: MATASSI TULIO ALEJANDRO | B26: =+_xlfn.XLOOKUP(carga[[#This Row],[PACIENTE]],BASE_PACIENTES_2026[PACIENTE],BASE_PACIENTES_2026[CUIL],0,0) -> 20 54476419 6 | C26: =+_xlfn.XLOOKUP(carga[[#This Row],[PACIENTE]],BASE_PACIENTES_2026[PACIENTE],BASE_PACIENTES_2026[O. SOCIAL],0,0) -> OSUTHGRA | D26: =+_xlfn.XLOOKUP(carga[[#This Row],[PACIENTE]],BASE_PACIENTES_2026[PACIENTE],BASE_PACIENTES_2026[MÓDULO],0,0) -> REHAB.INTENSIVO + CAI | E26: T.T | F26: Psico | G26: 1 | H26: CHIESA Gisella Erica Roxana | I26: Viernes | J26: 0.79166667 | K26: R.16 | L26: =+carga[[#This Row],[dia]] -> Viernes | M26: =+carga[[#This Row],[hora]] -> 0.79166667 | U26: =+MID(carga[[#This Row],[CUIL]],4,8) -> 54476419
B27: =+_xlfn.XLOOKUP(carga[[#This Row],[PACIENTE]],BASE_PACIENTES_2026[PACIENTE],BASE_PACIENTES_2026[CUIL],0,0) -> 0 | C27: =+_xlfn.XLOOKUP(carga[[#This Row],[PACIENTE]],BASE_PACIENTES_2026[PACIENTE],BASE_PACIENTES_2026[O. SOCIAL],0,0) -> 0 | D27: =+_xlfn.XLOOKUP(carga[[#This Row],[PACIENTE]],BASE_PACIENTES_2026[PACIENTE],BASE_PACIENTES_2026[MÓDULO],0,0) -> 0 | L27: =+carga[[#This Row],[dia]] -> 0 | M27: =+carga[[#This Row],[hora]] -> 0 | U27: =+MID(carga[[#This Row],[CUIL]],4,8)
A28: MOYA BRUNO CALIXTO | B28: =+_xlfn.XLOOKUP(carga[[#This Row],[PACIENTE]],BASE_PACIENTES_2026[PACIENTE],BASE_PACIENTES_2026[CUIL],0,0) -> 20 56764235 7 | C28: =+_xlfn.XLOOKUP(carga[[#This Row],[PACIENTE]],BASE_PACIENTES_2026[PACIENTE],BASE_PACIENTES_2026[O. SOCIAL],0,0) -> OSCEP (SIPSSA) | D28: =+_xlfn.XLOOKUP(carga[[#This Row],[PACIENTE]],BASE_PACIENTES_2026[PACIENTE],BASE_PACIENTES_2026[MÓDULO],0,0) -> REHAB.INTENSIVO + CAI | E28: T.T | F28: Fono | G28: 1 | H28: ARABIA Amira Nair | I28: Viernes | J28: 0.67708333 | L28: =+carga[[#This Row],[dia]] -> Viernes | M28: =+carga[[#This Row],[hora]] -> 0.67708333 | U28: =+MID(carga[[#This Row],[CUIL]],4,8) -> 56764235
A29: MONTENEGRO DEVRAN SAMUEL | B29: =+_xlfn.XLOOKUP(carga[[#This Row],[PACIENTE]],BASE_PACIENTES_2026[PACIENTE],BASE_PACIENTES_2026[CUIL],0,0) -> 20 55288753 1 | C29: =+_xlfn.XLOOKUP(carga[[#This Row],[PACIENTE]],BASE_PACIENTES_2026[PACIENTE],BASE_PACIENTES_2026[O. SOCIAL],0,0) -> IOSFA | D29: =+_xlfn.XLOOKUP(carga[[#This Row],[PACIENTE]],BASE_PACIENTES_2026[PACIENTE],BASE_PACIENTES_2026[MÓDULO],0,0) -> REHAB. SIMPLE + CAI | E29: T.T | F29: Fono | G29: 1 | H29: CASTRO Lucia Macarena | I29: Miercoles | J29: 0.79166667 | K29: R.3 | L29: =+carga[[#This Row],[dia]] -> Miercoles | M29: =+carga[[#This Row],[hora]] -> 0.79166667 | U29: =+MID(carga[[#This Row],[CUIL]],4,8) -> 55288753
A30: PATAGUA THEO VALENTIN | B30: =+_xlfn.XLOOKUP(carga[[#This Row],[PACIENTE]],BASE_PACIENTES_2026[PACIENTE],BASE_PACIENTES_2026[CUIL],0,0) -> 20 53627821 5 | C30: =+_xlfn.XLOOKUP(carga[[#This Row],[PACIENTE]],BASE_PACIENTES_2026[PACIENTE],BASE_PACIENTES_2026[O. SOCIAL],0,0) -> IOSFA | D30: =+_xlfn.XLOOKUP(carga[[#This Row],[PACIENTE]],BASE_PACIENTES_2026[PACIENTE],BASE_PACIENTES_2026[MÓDULO],0,0) -> REHAB. SIMPLE + CAI | E30: T.T | F30: Fono | G30: 1 | H30: GIMENEZ Agustina | I30: Viernes | J30: 0.76041667 | K30: R.6 | L30: =+carga[[#This Row],[dia]] -> Viernes | M30: =+carga[[#This Row],[hora]] -> 0.76041667 | U30: =+MID(carga[[#This Row],[CUIL]],4,8) -> 53627821
A31: CUELLO VALENTINO ANDRES | B31: =+_xlfn.XLOOKUP(carga[[#This Row],[PACIENTE]],BASE_PACIENTES_2026[PACIENTE],BASE_PACIENTES_2026[CUIL],0,0) -> 20 52962677 1 | C31: =+_xlfn.XLOOKUP(carga[[#This Row],[PACIENTE]],BASE_PACIENTES_2026[PACIENTE],BASE_PACIENTES_2026[O. SOCIAL],0,0) -> OSPEJ | D31: =+_xlfn.XLOOKUP(carga[[#This Row],[PACIENTE]],BASE_PACIENTES_2026[PACIENTE],BASE_PACIENTES_2026[MÓDULO],0,0) -> REHAB.SIMPLE | E31: T.T | F31: Fono | G31: 1 | H31: ARABIA Amira Nair | I31: Viernes | J31: 0.76041667 | L31: =+carga[[#This Row],[dia]] -> Viernes | M31: =+carga[[#This Row],[hora]] -> 0.76041667 | U31: =+MID(carga[[#This Row],[CUIL]],4,8) -> 52962677
A32: DIDYCZ ESTRADA MALENA VALENTINA | B32: =+_xlfn.XLOOKUP(carga[[#This Row],[PACIENTE]],BASE_PACIENTES_2026[PACIENTE],BASE_PACIENTES_2026[CUIL],0,0) -> 27 55522620 4 | C32: =+_xlfn.XLOOKUP(carga[[#This Row],[PACIENTE]],BASE_PACIENTES_2026[PACIENTE],BASE_PACIENTES_2026[O. SOCIAL],0,0) -> OSPENA | D32: =+_xlfn.XLOOKUP(carga[[#This Row],[PACIENTE]],BASE_PACIENTES_2026[PACIENTE],BASE_PACIENTES_2026[MÓDULO],0,0) -> REHAB.INTENSIVO + CAI | E32: T.M | F32: Fono | G32: 1 | H32: ARMOA Andrea Celeste | I32: Martes | J32: 0.33333333 | K32: R.11 | L32: =+carga[[#This Row],[dia]] -> Martes | M32: =+carga[[#This Row],[hora]] -> 0.33333333 | U32: =+MID(carga[[#This Row],[CUIL]],4,8) -> 55522620
A33: CORNEJO ANDULCE POOL VALENTINO | B33: =+_xlfn.XLOOKUP(carga[[#This Row],[PACIENTE]],BASE_PACIENTES_2026[PACIENTE],BASE_PACIENTES_2026[CUIL],0,0) -> 20 58557370 2 | C33: =+_xlfn.XLOOKUP(carga[[#This Row],[PACIENTE]],BASE_PACIENTES_2026[PACIENTE],BASE_PACIENTES_2026[O. SOCIAL],0,0) -> OSTACC | D33: =+_xlfn.XLOOKUP(carga[[#This Row],[PACIENTE]],BASE_PACIENTES_2026[PACIENTE],BASE_PACIENTES_2026[MÓDULO],0,0) -> REHAB.INTENSIVO + CAI | E33: T.M | F33: Fono | G33: 1 | H33: ARMOA Andrea Celeste | I33: Martes | J33: 0.47916667 | K33: R.11 | L33: =+carga[[#This Row],[dia]] -> Martes | M33: =+carga[[#This Row],[hora]] -> 0.47916667 | U33: =+MID(carga[[#This Row],[CUIL]],4,8) -> 58557370
A34: PAEZ FORMOSO LEON BENJAMIN | B34: =+_xlfn.XLOOKUP(carga[[#This Row],[PACIENTE]],BASE_PACIENTES_2026[PACIENTE],BASE_PACIENTES_2026[CUIL],0,0) -> 23 57744491 9 | C34: =+_xlfn.XLOOKUP(carga[[#This Row],[PACIENTE]],BASE_PACIENTES_2026[PACIENTE],BASE_PACIENTES_2026[O. SOCIAL],0,0) -> OSPE | D34: =+_xlfn.XLOOKUP(carga[[#This Row],[PACIENTE]],BASE_PACIENTES_2026[PACIENTE],BASE_PACIENTES_2026[MÓDULO],0,0) -> REHAB.INTENSIVO + CAI | E34: T.M | F34: Fono | G34: 1 | H34: ARMOA Andrea Celeste | I34: Martes | J34: 0.36458333 | K34: R.11 | L34: =+carga[[#This Row],[dia]] -> Martes | M34: =+carga[[#This Row],[hora]] -> 0.36458333 | U34: =+MID(carga[[#This Row],[CUIL]],4,8) -> 57744491
A35: MARTINEZ TOMAS | B35: =+_xlfn.XLOOKUP(carga[[#This Row],[PACIENTE]],BASE_PACIENTES_2026[PACIENTE],BASE_PACIENTES_2026[CUIL],0,0) -> 20 57944434 8 | C35: =+_xlfn.XLOOKUP(carga[[#This Row],[PACIENTE]],BASE_PACIENTES_2026[PACIENTE],BASE_PACIENTES_2026[O. SOCIAL],0,0) -> MEDIFÉ | D35: =+_xlfn.XLOOKUP(carga[[#This Row],[PACIENTE]],BASE_PACIENTES_2026[PACIENTE],BASE_PACIENTES_2026[MÓDULO],0,0) -> REHAB. SIMPLE + CAI | E35: T.M | F35: Fono | G35: 1 | H35: ARMOA Andrea Celeste | I35: Martes | J35: 0.36458333 | K35: R.11 | L35: =+carga[[#This Row],[dia]] -> Martes | M35: =+carga[[#This Row],[hora]] -> 0.36458333 | U35: =+MID(carga[[#This Row],[CUIL]],4,8) -> 57944434
A36: FALCON MALENA AGUSTINA | B36: =+_xlfn.XLOOKUP(carga[[#This Row],[PACIENTE]],BASE_PACIENTES_2026[PACIENTE],BASE_PACIENTES_2026[CUIL],0,0) -> 27 56063303 9 | C36: =+_xlfn.XLOOKUP(carga[[#This Row],[PACIENTE]],BASE_PACIENTES_2026[PACIENTE],BASE_PACIENTES_2026[O. SOCIAL],0,0) -> OSPEJ | D36: =+_xlfn.XLOOKUP(carga[[#This Row],[PACIENTE]],BASE_PACIENTES_2026[PACIENTE],BASE_PACIENTES_2026[MÓDULO],0,0) -> REHAB.INTENSIVO + CAI | E36: T.M | F36: Fono | G36: 1 | H36: ARMOA Andrea Celeste | I36: Martes | J36: 0.39583333 | K36: R.11 | L36: =+carga[[#This Row],[dia]] -> Martes | M36: =+carga[[#This Row],[hora]] -> 0.39583333 | U36: =+MID(carga[[#This Row],[CUIL]],4,8) -> 56063303
A37: PICHILINGUE ROMERO JUAN MARTIN | B37: =+_xlfn.XLOOKUP(carga[[#This Row],[PACIENTE]],BASE_PACIENTES_2026[PACIENTE],BASE_PACIENTES_2026[CUIL],0,0) -> 20 54306562 6 | C37: =+_xlfn.XLOOKUP(carga[[#This Row],[PACIENTE]],BASE_PACIENTES_2026[PACIENTE],BASE_PACIENTES_2026[O. SOCIAL],0,0) -> OSPICAL | D37: =+_xlfn.XLOOKUP(carga[[#This Row],[PACIENTE]],BASE_PACIENTES_2026[PACIENTE],BASE_PACIENTES_2026[MÓDULO],0,0) -> REHAB.INTENSIVO + CAI | E37: T.M | F37: Fono | G37: 1 | H37: ARMOA Andrea Celeste | I37: Martes | J37: 0.44791667 | K37: R.11 | L37: =+carga[[#This Row],[dia]] -> Martes | M37: =+carga[[#This Row],[hora]] -> 0.44791667 | U37: =+MID(carga[[#This Row],[CUIL]],4,8) -> 54306562
A38: LOPEZ SALAS LAUTARO MARTIN | B38: =+_xlfn.XLOOKUP(carga[[#This Row],[PACIENTE]],BASE_PACIENTES_2026[PACIENTE],BASE_PACIENTES_2026[CUIL],0,0) -> 20 54072524 2 | C38: =+_xlfn.XLOOKUP(carga[[#This Row],[PACIENTE]],BASE_PACIENTES_2026[PACIENTE],BASE_PACIENTES_2026[O. SOCIAL],0,0) -> OSTACC | D38: =+_xlfn.XLOOKUP(carga[[#This Row],[PACIENTE]],BASE_PACIENTES_2026[PACIENTE],BASE_PACIENTES_2026[MÓDULO],0,0) -> REHAB.INTENSIVO + CAI | E38: T.M | F38: Fono | G38: 1 | H38: BARRIA VAZQUEZ Luciana ALicia | I38: Lunes | J38: 0.44791667 | K38: R.5 | L38: =+carga[[#This Row],[dia]] -> Lunes | M38: =+carga[[#This Row],[hora]] -> 0.44791667 | U38: =+MID(carga[[#This Row],[CUIL]],4,8) -> 54072524
A39: PAZ CORDOBA BAUTISTA | B39: =+_xlfn.XLOOKUP(carga[[#This Row],[PACIENTE]],BASE_PACIENTES_2026[PACIENTE],BASE_PACIENTES_2026[CUIL],0,0) -> 20 56246858 8 | C39: =+_xlfn.XLOOKUP(carga[[#This Row],[PACIENTE]],BASE_PACIENTES_2026[PACIENTE],BASE_PACIENTES_2026[O. SOCIAL],0,0) -> OSGUIN (SERVIRED) | D39: =+_xlfn.XLOOKUP(carga[[#This Row],[PACIENTE]],BASE_PACIENTES_2026[PACIENTE],BASE_PACIENTES_2026[MÓDULO],0,0) -> REHAB.INTENSIVO + CAI | E39: T.M | F39: Fono | G39: 1 | H39: CASTRO Lucia Macarena | I39: Miercoles | J39: 0.39583333 | K39: R.10 | L39: =+carga[[#This Row],[dia]] -> Miercoles | M39: =+carga[[#This Row],[hora]] -> 0.39583333 | U39: =+MID(carga[[#This Row],[CUIL]],4,8) -> 56246858
A40: OBREGON JAZMIN | B40: =+_xlfn.XLOOKUP(carga[[#This Row],[PACIENTE]],BASE_PACIENTES_2026[PACIENTE],BASE_PACIENTES_2026[CUIL],0,0) -> 27 47577786 1 | C40: =+_xlfn.XLOOKUP(carga[[#This Row],[PACIENTE]],BASE_PACIENTES_2026[PACIENTE],BASE_PACIENTES_2026[O. SOCIAL],0,0) -> IOSFA | D40: =+_xlfn.XLOOKUP(carga[[#This Row],[PACIENTE]],BASE_PACIENTES_2026[PACIENTE],BASE_PACIENTES_2026[MÓDULO],0,0) -> REHAB.SIMPLE | E40: T.M | F40: Kine | G40: 1 | H40: CONDORI Jose Hugo | I40: Jueves | J40: 0.51041667 | K40: R.Gimnasio | L40: =+carga[[#This Row],[dia]] -> Jueves | M40: =+carga[[#This Row],[hora]] -> 0.51041667 | U40: =+MID(carga[[#This Row],[CUIL]],4,8) -> 47577786
...

Sheet TURNERO T. MAÑANA
D6: turno | E6: (Varios elementos)
D8: TURNERO PROFESIONAL | H8: dia
D9: HORARIO | E9: PROFESIONAL | F9: SERVICIO | G9: PACIENTE | H9: Lunes | I9: Miercoles | J9: Viernes
D10: 0.44791667 | E10: FERREYRA Jennifer Magali | F10: Psicomotricidad | G10: HEREDIA BAUTISTA SAMUEL | H10: ----- | I10: ----- | J10: 1
D11: 0.44791667 | E11: FERREYRA Jennifer Magali | F11: Psicomotricidad | G11: ESQUIVEL ALVARO SAMUEL | H11: 1 | I11: 1 | J11: -----
D12: 0.47916667 | E12: FERREYRA Jennifer Magali | F12: Psicomotricidad | G12: ALMADA MARTINEZ BAUTISTA BENJAMIN | H12: 1 | I12: ----- | J12: -----
D13: 0.47916667 | E13: FERREYRA Jennifer Magali | F13: Psicomotricidad | G13: FERNADEZ THIAGO | H13: ----- | I13: 1 | J13: 1

Sheet TURNERO T. TARDE
D6: turno | E6: T.T
D8: TURNERO PROFESIONAL | H8: dia
D9: HORARIO | E9: PROFESIONAL | F9: SERVICIO | G9: PACIENTE

Sheet LISTADOS
B2: Pacientes | D2: Profesionales | E2: Especialidad | G2: Servicios | I2: Horarios | K2: Dias | M2: Modulos | O2: OBRAS SOCIALES | U2: Pacientes | W2: ACCION
B3: {=+_xlfn._xlws.SORT(_xlfn.UNIQUE(BASE_PACIENTES_2026[PACIENTE]),1,1)} -> ABENTE BENJAMIN NICOLAS | D3: {=+_xlfn._xlws.SORT(_xlfn.UNIQUE(tbl_Horarios[Apellido y Nombre]),1,1)} | E3: =+IFERROR(VLOOKUP(D3,HORARIOS!A:B,2,0),"") -> 0 | G3: Fono | I3: 0.33333333 | K3: Lunes | M3: SIMPLE | O3: APROSS | S3: CONSULTORIOS | U3: {=+_xlfn.UNIQUE(carga[PACIENTE])} -> MOYANO SANTINO LEONEL | V3: =+VLOOKUP(U3,carga[[PACIENTE]:[TURNO]],5,0) -> T.T | W3: ALTA
B4: ACOSTA CELESTE SOLEDAD | D4: ALMADA Luciana | E4: =+IFERROR(VLOOKUP(D4,HORARIOS!A:B,2,0),"") -> Psicomotricidad | G4: TO | I4: 0.36458333 | K4: Martes | M4: INTENSIVO | O4: CAJA DE SANTA CRUZ (GEA 310) | Q4: R. | R4: 1 | S4: =+CONCATENATE(Q4,R4) -> R.1 | U4: ALANIS GINA | V4: =+VLOOKUP(U4,carga[[PACIENTE]:[TURNO]],5,0) -> T.T | W4: BAJA
B5: AGUERO TEVEZ JULIANA | D5: ANSELMI Juliana Lourdes | E5: =+IFERROR(VLOOKUP(D5,HORARIOS!A:B,2,0),"") -> Psicopedagogia | G5: Psm | I5: 0.39583333 | K5: Miercoles | M5: SIMPLE + CAI | O5: GEA PREPAGA | Q5: R. | R5: 1B | S5: =+CONCATENATE(Q5,R5) -> R.1B | U5: FIGUEROA IVAN PEDRO | V5: =+VLOOKUP(U5,carga[[PACIENTE]:[TURNO]],5,0) -> T.T | W5: MODIFICACION
B6: AGUIRRE ALEX ANDRES | D6: ARANDA Karina Alejandra | E6: =+IFERROR(VLOOKUP(D6,HORARIOS!A:B,2,0),"") -> Kinesiologia | G6: Kine | I6: 0.44791667 | K6: Jueves | M6: INTENSIVO +CAI | O6: IOSFA | Q6: R. | R6: 2 | S6: =+CONCATENATE(Q6,R6) -> R.2 | U6: PERALTA ISAAC | V6: =+VLOOKUP(U6,carga[[PACIENTE]:[TURNO]],5,0) -> T.T | W6: PENDIENTE
B7: AGUIRRE FRANCISCO SIMON | D7: ARMOA Andrea Celeste | E7: =+IFERROR(VLOOKUP(D7,HORARIOS!A:B,2,0),"") -> Fonoaudiologia | G7: Psico | I7: 0.47916667 | K7: Viernes | M7: CAI | O7: OMINT | Q7: R. | R7: 3 | S7: =+CONCATENATE(Q7,R7) -> R.3 | U7: CORNEJO SAMIENTA FACUNDO NICOLAS | V7: =+VLOOKUP(U7,carga[[PACIENTE]:[TURNO]],5,0) -> T.T
B8: AGUIRRE LEVY UNAY | D8: BARRIA VAZQUEZ Luciana ALicia | E8: =+IFERROR(VLOOKUP(D8,HORARIOS!A:B,2,0),"") -> Fonoaudiologia | G8: Psp | I8: 0.51041667 | M8: PSICO + CAI | O8: OSADEF | Q8: R. | R8: 4 | S8: =+CONCATENATE(Q8,R8) -> R.4 | U8: GOMEZ SANTIAGO BENJAMIN | V8: =+VLOOKUP(U8,carga[[PACIENTE]:[TURNO]],5,0) -> T.M
B9: AGUIRRE VILLAMIZAR OLIVER JOSE | D9: BASUALDO Candela Ariadna | E9: =+IFERROR(VLOOKUP(D9,HORARIOS!A:B,2,0),"") -> Psicopedagogia | G9: Psp Cai | I9: 0.54166667 | O9: OSBLYCA (SERVIRED) | Q9: R. | R9: 5 | S9: =+CONCATENATE(Q9,R9) -> R.5 | U9: DESIMONE LUZ JAZMIN | V9: =+VLOOKUP(U9,carga[[PACIENTE]:[TURNO]],5,0) -> T.T
B10: ALANIS GINA | D10: BENEDETTO Andres Esteban | E10: =+IFERROR(VLOOKUP(D10,HORARIOS!A:B,2,0),"") -> Psicologia | G10: Psico Fliar | I10: 0.58333333 | O10: OSCE (CERAMISTAS) | Q10: R. | R10: 6 | S10: =+CONCATENATE(Q10,R10) -> R.6 | U10: FURTADO JUAN JOSE | V10: =+VLOOKUP(U10,carga[[PACIENTE]:[TURNO]],5,0) -> T.T
B11: ALAVAR BRIAN ANTONY | D11: CASTAGNO Melina Eliana | E11: =+IFERROR(VLOOKUP(D11,HORARIOS!A:B,2,0),"") -> Terapia Ocupacional | G11: Psico Cai | I11: 0.61458333 | O11: SIPSSA (OSCEP) | Q11: R. | R11: 7 | S11: =+CONCATENATE(Q11,R11) -> R.7 | U11: MOYA BRUNO CALIXTO | V11: =+VLOOKUP(U11,carga[[PACIENTE]:[TURNO]],5,0) -> T.T
B12: ALDERETE LIAN ALEJANDRO | D12: CASTRO Lucia Macarena | E12: =+IFERROR(VLOOKUP(D12,HORARIOS!A:B,2,0),"") -> Fonoaudiologia | G12: Fono Pami | I12: 0.64583333 | O12: OSDE | Q12: R. | R12: TO | S12: =+CONCATENATE(Q12,R12) -> R.TO | U12: VIVANCO CABRERA MATEO JOAQUIN | V12: =+VLOOKUP(U12,carga[[PACIENTE]:[TURNO]],5,0) -> T.T
B13: ALMADA EZCURRA SOFIA | D13: CHIESA Gisella Erica Roxana | E13: =+IFERROR(VLOOKUP(D13,HORARIOS!A:B,2,0),"") -> Psicologia | G13: Psico Pami | I13: 0.67708333 | O13: OSECAC | Q13: R. | R13: Trab. Social | S13: =+CONCATENATE(Q13,R13) -> R.Trab. Social | U13: SUAREZ CELESTE ABRIL | V13: =+VLOOKUP(U13,carga[[PACIENTE]:[TURNO]],5,0) -> T.T
B14: ALMADA MARTINEZ BAUTISTA BENJAMIN | D14: COLINA Gloria Sofia | E14: =+IFERROR(VLOOKUP(D14,HORARIOS!A:B,2,0),"") -> Terapia Ocupacional | I14: 0.72916667 | O14: OSEIV | Q14: R. | R14: 10 | S14: =+CONCATENATE(Q14,R14) -> R.10 | U14: AGUIRRE VILLAMIZAR OLIVER JOSE | V14: =+VLOOKUP(U14,carga[[PACIENTE]:[TURNO]],5,0) -> T.T
B15: AMAYA TADEO BENJAMIN | D15: CONDORI Jose Hugo | E15: =+IFERROR(VLOOKUP(D15,HORARIOS!A:B,2,0),"") -> Kinesiologia | I15: 0.76041667 | O15: OSETYA (EMPLEADOS TEXTILES) | Q15: R. | R15: 11 | S15: =+CONCATENATE(Q15,R15) -> R.11 | U15: MACHADO VIDELA BENJAMIN FRANCESCO | V15: =+VLOOKUP(U15,carga[[PACIENTE]:[TURNO]],5,0) -> T.T
B16: ANASTASIA STELLA MARIS | D16: CORTEZ Carolina Anahi | E16: =+IFERROR(VLOOKUP(D16,HORARIOS!A:B,2,0),"") -> Psicopedagogia | I16: 0.79166667 | O16: OSCEARA | Q16: R. | R16: 12 | S16: =+CONCATENATE(Q16,R16) -> R.12 | U16: 0 | V16: =+VLOOKUP(U16,carga[[PACIENTE]:[TURNO]],5,0) -> #N/A
B17: ANTEZANA ESCOBAR THIAGO LUIS | D17: CRIADO Sabrina Tamara | E17: =+IFERROR(VLOOKUP(D17,HORARIOS!A:B,2,0),"") -> Psicomotricidad | O17: OSFE | Q17: R. | R17: 13 | S17: =+CONCATENATE(Q17,R17) -> R.13 | U17: BETOLLI CATALINA | V17: =+VLOOKUP(U17,carga[[PACIENTE]:[TURNO]],5,0) -> T.M
B18: ARCE BENICIO | D18: CUELLO Florencia Patricia | E18: =+IFERROR(VLOOKUP(D18,HORARIOS!A:B,2,0),"") -> Psicologia | O18: OSMATA | Q18: R. | R18: 14 | S18: =+CONCATENATE(Q18,R18) -> R.14 | U18: CATRAMBONI FABRIZZIO FRANCESCO | V18: =+VLOOKUP(U18,carga[[PACIENTE]:[TURNO]],5,0) -> T.T
B19: ARGUELLO THOMAS ALEJO | D19: de MEDEIROS Micaela | E19: =+IFERROR(VLOOKUP(D19,HORARIOS!A:B,2,0),"") -> Psicologia | O19: OSME (UNIMED) | Q19: R. | R19: 15 | S19: =+CONCATENATE(Q19,R19) -> R.15 | U19: REYES FERREYRA AIXA YAZMIN | V19: =+VLOOKUP(U19,carga[[PACIENTE]:[TURNO]],5,0) -> T.T
B20: ARRIETA BENJAMIN | D20: DIAZ NIEVAS Andrea Celeste | E20: =+IFERROR(VLOOKUP(D20,HORARIOS!A:B,2,0),"") -> Psicomotricidad | O20: OSMTT(SERVIRED) | Q20: R. | R20: 16 | S20: =+CONCATENATE(Q20,R20) -> R.16 | U20: OBREGON JAZMIN | V20: =+VLOOKUP(U20,carga[[PACIENTE]:[TURNO]],5,0) -> T.M
B21: ARROYO OSCAR ALFREDO | D21: DOMINGUEZ Mercedes Lorena | E21: =+IFERROR(VLOOKUP(D21,HORARIOS!A:B,2,0),"") -> Psicologia | O21: OSPATRONES | Q21: R. | R21: 17 | S21: =+CONCATENATE(Q21,R21) -> R.17 | U21: MATASSI TULIO ALEJANDRO | V21: =+VLOOKUP(U21,carga[[PACIENTE]:[TURNO]],5,0) -> T.T
B22: ASTUDILLO PABLO ISMAEL | D22: FERNANDEZ Maria Emilia | E22: =+IFERROR(VLOOKUP(D22,HORARIOS!A:B,2,0),"") -> Fonoaudiologia | O22: OSPAV | Q22: R. | R22: 18 | S22: =+CONCATENATE(Q22,R22) -> R.18 | U22: MONTENEGRO DEVRAN SAMUEL | V22: =+VLOOKUP(U22,carga[[PACIENTE]:[TURNO]],5,0) -> T.T
B23: AVACA MATEO BENJAMIN | D23: FERNANDEZ WOLFF Katerin | E23: =+IFERROR(VLOOKUP(D23,HORARIOS!A:B,2,0),"") -> Psicologia | O23: OSPE | Q23: R. | R23: 19 | S23: =+CONCATENATE(Q23,R23) -> R.19 | U23: PATAGUA THEO VALENTIN | V23: =+VLOOKUP(U23,carga[[PACIENTE]:[TURNO]],5,0) -> T.T
B24: AVALOS LAUTARO JOAQUÍN | D24: FERREYRA Jennifer Magali | E24: =+IFERROR(VLOOKUP(D24,HORARIOS!A:B,2,0),"") -> Psicomotricidad | O24: OSPAT | Q24: R. | R24: 20 Pami | S24: =+CONCATENATE(Q24,R24) -> R.20 Pami | U24: CUELLO VALENTINO ANDRES | V24: =+VLOOKUP(U24,carga[[PACIENTE]:[TURNO]],5,0) -> T.T
B25: BALTAZAR BERNAL ALISON | D25: FLEIDERMAN Paula | E25: =+IFERROR(VLOOKUP(D25,HORARIOS!A:B,2,0),"") -> Psicologia | O25: OSPEC | Q25: R. | R25: Estim. 1 | S25: =+CONCATENATE(Q25,R25) -> R.Estim. 1 | U25: DIDYCZ ESTRADA MALENA VALENTINA | V25: =+VLOOKUP(U25,carga[[PACIENTE]:[TURNO]],5,0) -> T.M
B26: BALTAZAR BERNAL ALISON BELEN | D26: GARCIA Nadia | E26: =+IFERROR(VLOOKUP(D26,HORARIOS!A:B,2,0),"") -> Psicopedagogia | O26: OSPECON | Q26: R. | R26: Estim. 2 | S26: =+CONCATENATE(Q26,R26) -> R.Estim. 2 | U26: CORNEJO ANDULCE POOL VALENTINO | V26: =+VLOOKUP(U26,carga[[PACIENTE]:[TURNO]],5,0) -> T.M
B27: BALTAZAR BERNAL HANNA MARTINA | D27: GIMENEZ Agustina | E27: =+IFERROR(VLOOKUP(D27,HORARIOS!A:B,2,0),"") -> Fonoaudiologia | O27: OSPECOR | Q27: R. | R27: Gimnasio | S27: =+CONCATENATE(Q27,R27) -> R.Gimnasio | U27: PAEZ FORMOSO LEON BENJAMIN | V27: =+VLOOKUP(U27,carga[[PACIENTE]:[TURNO]],5,0) -> T.M
B28: BALTAZAR BERNAL ISABELLA MILENA | D28: GIRAUDO MILAGROS VIRGINIA | E28: =+IFERROR(VLOOKUP(D28,HORARIOS!A:B,2,0),"") -> Fonoaudiologia | O28: OSPEJ | Q28: CAI. | R28: 1 | S28: =+CONCATENATE(Q28,R28) -> CAI.1 | U28: MARTINEZ TOMAS | V28: =+VLOOKUP(U28,carga[[PACIENTE]:[TURNO]],5,0) -> T.M
B29: BARRAZA FABRIZIO BENJAMÍN | D29: GOMEZ Agustina Daniela | E29: =+IFERROR(VLOOKUP(D29,HORARIOS!A:B,2,0),"") -> Fonoaudiologia | O29: OSPENA | Q29: CAI. | R29: 2 | S29: =+CONCATENATE(Q29,R29) -> CAI.2 | U29: FALCON MALENA AGUSTINA | V29: =+VLOOKUP(U29,carga[[PACIENTE]:[TURNO]],5,0) -> T.M
B30: BARRERA WALTER DANIEL | D30: GOMEZ MARTINA Carolina | E30: =+IFERROR(VLOOKUP(D30,HORARIOS!A:B,2,0),"") -> Psicomotricidad | O30: OSPES | Q30: CAI. | R30: 3 | S30: =+CONCATENATE(Q30,R30) -> CAI.3 | U30: PICHILINGUE ROMERO JUAN MARTIN | V30: =+VLOOKUP(U30,carga[[PACIENTE]:[TURNO]],5,0) -> T.M
B31: BARRIONUEVO ALAN EZEQUIEL | D31: HEREDIA LIZARAZU Lucia | E31: =+IFERROR(VLOOKUP(D31,HORARIOS!A:B,2,0),"") -> Psicomotricidad | O31: OSPIC | Q31: CAI. | R31: Recep. | S31: =+CONCATENATE(Q31,R31) -> CAI.Recep. | U31: LOPEZ SALAS LAUTARO MARTIN | V31: =+VLOOKUP(U31,carga[[PACIENTE]:[TURNO]],5,0) -> T.M
B32: BARRIONUEVO ZAIRA MAYLEN | D32: LAZO Ana Magdalena | E32: =+IFERROR(VLOOKUP(D32,HORARIOS!A:B,2,0),"") -> Fonoaudiologia | O32: OSPICAL | Q32: CAI. | R32: Escrit. 1 | S32: =+CONCATENATE(Q32,R32) -> CAI.Escrit. 1 | U32: PAZ CORDOBA BAUTISTA | V32: =+VLOOKUP(U32,carga[[PACIENTE]:[TURNO]],5,0) -> T.M
B33: BARRIOS RIVERO CAMILA ARIADNA | D33: LEMA Luz Candela | E33: =+IFERROR(VLOOKUP(D33,HORARIOS!A:B,2,0),"") -> Psicopedagogia | O33: OSPIM | Q33: CAI. | R33: Escrit. 2 | S33: =+CONCATENATE(Q33,R33) -> CAI.Escrit. 2 | U33: VIJARRA JOAQUIN EMILIANO | V33: =+VLOOKUP(U33,carga[[PACIENTE]:[TURNO]],5,0) -> T.T
B34: BAZAN LOPEZ THOMAS DAVID | D34: LORENZATTO Delfina Maria | E34: =+IFERROR(VLOOKUP(D34,HORARIOS!A:B,2,0),"") -> Psicomotricidad | O34: OSPJTAP | U34: HEREDIA JOAQUIN | V34: =+VLOOKUP(U34,carga[[PACIENTE]:[TURNO]],5,0) -> T.T
B35: BETTOLLI CATALINA | D35: MARTINEZ Lucas | E35: =+IFERROR(VLOOKUP(D35,HORARIOS!A:B,2,0),"") -> Kinesiologia | O35: OSPLAD | U35: GUTIERREZ OLAVE CRISTOBAL NICOLAS | V35: =+VLOOKUP(U35,carga[[PACIENTE]:[TURNO]],5,0) -> T.T
B36: BONZA VAZQUEZ BENJAMIN | D36: MENDEZ Alejandra Carolina | E36: =+IFERROR(VLOOKUP(D36,HORARIOS!A:B,2,0),"") -> Psicomotricidad | O36: OSPLYFC | U36: ROBIN FELIPE BENJAMIN | V36: =+VLOOKUP(U36,carga[[PACIENTE]:[TURNO]],5,0) -> T.T
B37: BRAVO VITORGAN EZEQUIEL | D37: MOLINA BRENDA | E37: =+IFERROR(VLOOKUP(D37,HORARIOS!A:B,2,0),"") -> Psicomotricidad | O37: OSPOCE (SWISS MEDICAL) | U37: CAROLI VILLARREAL AXEL BENJAMIN | V37: =+VLOOKUP(U37,carga[[PACIENTE]:[TURNO]],5,0) -> T.T
B38: BRUNO MARCOS GABRIEL | D38: OLIVA Lucas Julian | E38: =+IFERROR(VLOOKUP(D38,HORARIOS!A:B,2,0),"") -> Psicologia | O38: OSPRERA | U38: PEREYRA LUCCA PATRICIO | V38: =+VLOOKUP(U38,carga[[PACIENTE]:[TURNO]],5,0) -> T.M
B39: BULACIO SILVIA CRISTINA | D39: OLOCCO Maria Gabriela | E39: =+IFERROR(VLOOKUP(D39,HORARIOS!A:B,2,0),"") -> Psicologia | O39: OSSACRA | U39: JAZBEC JEREMIAS | V39: =+VLOOKUP(U39,carga[[PACIENTE]:[TURNO]],5,0) -> T.T
B40: BUSTAMANTE MATEO JOEL | D40: PAPA ARTERO Eimi Luhué | E40: =+IFERROR(VLOOKUP(D40,HORARIOS!A:B,2,0),"") -> Fonoaudiologia | O40: OSSSB | U40: VALLE CARRIZO MATEO VALENTINO | V40: =+VLOOKUP(U40,carga[[PACIENTE]:[TURNO]],5,0) -> T.T
B41: BUSTOS GUZMAN MALEN AGUSTINA | D41: PEPELLIN Maria de los Angeles | E41: =+IFERROR(VLOOKUP(D41,HORARIOS!A:B,2,0),"") -> Psicologia | O41: OSSURRBAC | U41: CACIVA MINASSIAN MORENA | V41: =+VLOOKUP(U41,carga[[PACIENTE]:[TURNO]],5,0) -> T.T
...

Sheet TURNERO TODOS
B7: TURNERO PROFESIONAL | F7: dia
B8: Hora | C8: PROFESIONAL | D8: Servicio | E8: PACIENTE | F8: Lunes | G8: Martes | H8: Miercoles | I8: Jueves | J8: Viernes
B9: 0.33333333 | C9: GOMEZ MARTINA Carolina | D9: Psicomotricidad | E9: AVACA MATEO BENJAMIN | J9: 1
B10: 0.33333333 | C10: GOMEZ MARTINA Carolina | D10: Psicomotricidad | E10: MORENO SUAREZ JOAQUIN | G10: 1
B11: 0.33333333 | C11: GOMEZ MARTINA Carolina | D11: Psicomotricidad | E11: PEREZ LUIS SANTIAGO | F11: 1 | H11: 1
B12: 0.33333333 | C12: GOMEZ MARTINA Carolina | D12: Psicomotricidad | E12: (en blanco)
B13: 0.33333333 | C13: HEREDIA LIZARAZU Lucia | D13: Psicomotricidad | E13: MORENO SUAREZ JOAQUIN | I13: 1
B14: 0.33333333 | C14: HEREDIA LIZARAZU Lucia | D14: Psicomotricidad | E14: (en blanco)
B15: 0.33333333 | C15: MENDEZ Alejandra Carolina | D15: Psicomotricidad | E15: PEREZ AZUL CATALINA | J15: 1
B16: 0.33333333 | C16: MENDEZ Alejandra Carolina | D16: Psicomotricidad | E16: (en blanco)
B17: 0.33333333 | C17: MOLINA BRENDA | D17: Psicomotricidad | E17: ARCE BENICIO | G17: 1 | I17: 1
B18: 0.33333333 | C18: MOLINA BRENDA | D18: Psicomotricidad | E18: FALCON MALENA AGUSTINA | I18: 1
B19: 0.33333333 | C19: MOLINA BRENDA | D19: Psicomotricidad | E19: PEREYRA LUCCA PATRICIO | H19: 1
B20: 0.33333333 | C20: FERREYRA Jennifer Magali | D20: Psicomotricidad | E20: CARISSIMO CACERES JUAN AGUSTIN | H20: 1 | J20: 1
B21: 0.33333333 | C21: FERREYRA Jennifer Magali | D21: Psicomotricidad | E21: MONSERRAT GARCIA JONAS EZEQUIEL | F21: 1 | H21: 1
B22: 0.33333333 | C22: FERREYRA Jennifer Magali | D22: Psicomotricidad | E22: MONTENEGRO JESUS BAUTISTA | J22: 1
B23: 0.36458333 | C23: GOMEZ MARTINA Carolina | D23: Psicomotricidad | E23: AVACA MATEO BENJAMIN | H23: 1
B24: 0.36458333 | C24: GOMEZ MARTINA Carolina | D24: Psicomotricidad | E24: DIDYCZ ESTRADA MALENA VALENTINA | G24: 1
B25: 0.36458333 | C25: GOMEZ MARTINA Carolina | D25: Psicomotricidad | E25: GONZALEZ DUARTE BASTIAN ALEJANDRO | H25: 1
B26: 0.36458333 | C26: GOMEZ MARTINA Carolina | D26: Psicomotricidad | E26: RIOS AMBAR | F26: 1 | I26: 1
B27: 0.36458333 | C27: GOMEZ MARTINA Carolina | D27: Psicomotricidad | E27: (en blanco)
B28: 0.36458333 | C28: HEREDIA LIZARAZU Lucia | D28: Psicomotricidad | E28: GONZALEZ DUARTE BASTIAN ALEJANDRO | I28: 1
B29: 0.36458333 | C29: HEREDIA LIZARAZU Lucia | D29: Psicomotricidad | E29: RODRIGUEZ SANTINO | G29: 1 | I29: 1
B30: 0.36458333 | C30: MENDEZ Alejandra Carolina | D30: Psicomotricidad | E30: OVIEDO MAXIMO SAMUEL | H30: 1 | J30: 1
B31: 0.36458333 | C31: MOLINA BRENDA | D31: Psicomotricidad | E31: MOYANO MATEO JULIAN | H31: 1
B32: 0.36458333 | C32: MOLINA BRENDA | D32: Psicomotricidad | E32: SORRONDEGUI NOAH GABRIEL | G32: 1 | I32: 1
B33: 0.36458333 | C33: FERREYRA Jennifer Magali | D33: Psicomotricidad | E33: ESPINDOLA ARCE SOFIA | H33: 1 | J33: 1
B34: 0.36458333 | C34: FERREYRA Jennifer Magali | D34: Psicomotricidad | E34: MANCINI MEDINA UZIEL JEREMIAS | F34: 1
B35: 0.39583333 | C35: GOMEZ MARTINA Carolina | D35: Psicomotricidad | E35: ALDERETE LIAN ALEJANDRO | G35: 1 | I35: 1
B36: 0.39583333 | C36: GOMEZ MARTINA Carolina | D36: Psicomotricidad | E36: ASTUDILLO PABLO ISMAEL | G36: 1
B37: 0.39583333 | C37: GOMEZ MARTINA Carolina | D37: Psicomotricidad | E37: DIAZ ROMAN VALENTIN | H37: 1 | J37: 1
B38: 0.39583333 | C38: GOMEZ MARTINA Carolina | D38: Psicomotricidad | E38: DIDYCZ ESTRADA MALENA VALENTINA | J38: 1
